Workbook
Name Catégories: 'Aide aux risques'!$B$43:$B$48
Name Introduction: [1]!ok
Name Introduction: [1]!ok
Name Introduction: [1]!ok
Name Introduction: [1]!ok
Name Introduction: [1]!ok
Name Introduction: [1]!ok
Name mois: #REF!
Name Niveaux: #REF!
Name ok: [1]!ok
Name ok: [1]!ok
Name ok: [1]!ok
Name ok: [1]!ok
Name ok: [1]!ok
Name ok: [1]!ok
Name ok: [1]!ok
Name Sources: #REF!
Name travel: '[2]Suivi Travel'!$U$7

Sheet Guide utilisateur
B1: GUIDE
B3: Objectif
C4: Ce guide vise à facilier l'utilisation et prise en main de 2 outils de pilotage des risques contenus dans ce fichier :
C5: 1. "Pilotage risques et actions"
C6: 2. "AMDEC"
B8: A qui s'adresse t-il ?
C9: Cet outil est destiné à l'ensemble des pôles métier FMS : My Log, My System; MVP, FMS ID, My Work, Service(s) Support (Transverses)
C10: Il s'adresse aux managers opérationnels, de direction et/ou de services support (transverse) en charge de piloter les risques d'un projet/processus.
B12: 1 | C12: Introduction
C13: Ce préambule décrit, en 5 étapes, la méthodologie de gestion des risques. Vous y trouverez la définition de termes à connaître avant d'appréhender les outils du fichier.
B15: 2 | C15: Aide aux risques
C16: Informations à utiliser pour compléter les colonnes "catégorie" et "description du risque" de l'outil "Risques et Actions"
C17: Il contient une liste d'exemples (non exhaustive) de risques classés en 6 catégories.
B19: 3 | C19: Risques et actions
C20: L'implémentation de cet outil se fait en 3 étapes :
C21: 1. Identifier le risque | D21: 2. Evaluer le risque | E21: 3. Construire le plan d'action
C23: Comment évaluer un risque ?
C24: Une fois le risque identifié, une évaluation de sa criticité est nécessaire. Elle est réalisée via 2 paramètres, la probabilité/occurence et la gravité.
C26: Matrice / grille de cotation
D28: Gravité
D29: Très Haute | E29: Moyen | F29: Moyen | G29: Fort | H29: Très fort
D30: Haute | E30: Faible | F30: Moyen | G30: Fort | H30: Très fort
D31: Moyen | E31: Faible | F31: Moyen | G31: Fort | H31: Fort
D32: Faible | E32: Faible | F32: Faible | G32: Moyen | H32: Moyen | I32: seuil de déclenchement d'action
E33: Faible | F33: Moyen | G33: Haute | H33: Très Haute
D34: Probabilité*
E36: Faible | F36: Action non requise
E37: Moyen | F37: Action requise
E38: Fort | F38: Action requise
E39: Très fort | F39: Action requise
D41: Echelle de probabilité / Occurrence
D43: Faible | E43: Isolé - peu probable - moins d'1 fois par an ou 1 fois toutes les 10 000 pièces produites
D44: Moyen | E44: Peu fréquent - 1 à 4 fois par an ou 1 fois toutes les 3000 pièces produites
D45: Fort | E45: Dysfonctionnement fréquent - 1 à 3 fois par mois ou 1 fois toutes les 500 pièces produites
D46: Très fort | E46: Dysfonctionnement répété - entre 1 fois par semaine et tous les jours ou 1 fois entre 1-50 pièces
D48: Echelle de Gravité
D49: Faible | E49: Non détectable par le client et incidence faible - Perte mineure sur le service.
D50: Moyen | E50: Détectable par le client et incidence induisant une perte de service. Il existe une solution de contournement afin de restaurer le service.
D51: Fort | E51: Détectable par le client et incidence induisant une perte importante de service. Pas de solution de contournement. Requiert une action afin de restaurer le service.
D52: Très fort | E52: Détectable par le client et incidence majeure. Probabilité de perte du client. Requiert une action afin de restaurer le service.
...

Sheet Introduction
C1: INTRODUCTION
C3: La gestion des risques
C4: Un risque est un danger éventuel plus ou moins prévisible. Tous les risques ne sont pas prévisibles.
C5: Le pilotage des risques passe par un questionnement régulier et une analyse des risques à intégrer aux réunions de suivi hebdomadaire des activités de votre projet/processus.
C7: Méthodologie en 5 étapes
C25: Etape 1 : Identifier les risques
C38: Etape 2 : Analyser et évaluer les risques
C42: La criticité est :
C43: -une aide à la hiérarchisation des risque
C44: -une aide pour décider des actions prioritaires
C46: La définition de seuils conditionne la mise en place d’actions:
C47: Tout ce qui est au-dessus du seuil nécessite la mise en place d’actions
... C86: Attention : Si le risque augmente et passe au-dessus du seuil défini, des actions doivent être mises en place pour réduire le risque

Sheet Aide aux risques
B2: Aide aux risques
B4: Diagramme d'Ishikawa
B13: Catégories et types de risques
B14: Les sources possibles de risques peuvent être trouvées dans les domaines de l'Infrastructure, Commercial, Technique, Personnel ou Qualité telle que détaillée dans les domaines suivants (liste non-exhaustive :
C16: Infrastructure | D16: Commercial | E16: Technique | F16: Ressources Humaines | G16: Qualité | H16: Organisation
C17: Système IT | D17: Prix | E17: Étendue de l'expertise technique en dehors des capacité et périmètre | F17: Manque de ressources et de compétences particulières | G17: Ajustement avec le scope approuvée | H17: Ajustement avec le périmètre approuvé
C18: Disponibilité de l'ordinateur | D18: Utilisation de fournisseurs désignés par le client | E18: Ambiguïté ou manque de compréhension de conditions | F18: Besoins de formation | G18: Exigences client spéciales | H18: Organisation équipe
C19: Sauvegarde de données | D19: Besoin de nouveaux fournisseurs | E19: Données manquantes | F19: Problèmes de santé et de sécurité | G19: Implications des fournisseurs | H19: Organisation activités
C20: Sécurité du bâtiment | D20: Clauses pénales et responsabilités | E20: Nouveau processus et procédures | F20: Les problèmes de sécurité | G20: Normes de contrôle de configuration à appliquer | H20: Charge de travail
C21: Reprise après sinistre | D21: Attentes de garantie | E21: Processus et critères d'acceptation | F21: Satisfaction salarié | G21: Autorisations et approbations requises | H21: Continuité de service
C22: Système de messagerie | D22: Conditions commerciales exceptionnelles de toute nature | E22: Interfaces | F22: Turn Over | G22: Exigences et spécifications de clients
C23: Détection et évacuation incendie | D23: Problèmes de taux de change | E23: Responsabilité/Délégation d'autorité | G23: Plan Qualité en particulier pour les activités non standardisées
C24: Meubles, etc... | D24: Taille du contrat | E24: Niveaux de compétence existants | G24: Exigences légales et réglementaires
C25: Adéquation des moyens matériels aux besoins de la mission | D25: Licence d'exportation | E25: Complexité | G25: Participation des clients
C26: Sécurité du bâtiment/site | D26: Propriétés intellectuelles | E26: Technologies de l'information et de la communication, etc... | G26: Qualité des livrables (OQD)
C27: Reprise après sinistre | D27: Partenariat /Offshore | G27: Délais et jalons (OTD)
C28: Détection et évacuation incendie | D28: Support produit demandé | G28: Satisfaction client
C29: Logiciels et autres équipements requis | D29: Implication de groupe, etc…
D30: Commande
D31: Bon de livraison
D32: Conditions commerciales exceptionnelles
D33: Partenariat
D34: Facturation
D35: Contractualisation
D36: Clauses pénales et responsabilités
D37: Licence d'exportation
D38: Propriétés intellectuelles
B42: Catégories
B43: =C16 -> Infrastructure
B44: =D16 -> Commercial
B45: =E16 -> Technique
B46: =F16 -> Ressources Humaines
B47: =G16 -> Qualité
B48: =H16 -> Organisation

Sheet Risques et Actions
A2: Pilotage des risques et actions
A4: Nom du pôle métier/processus : | C4: Support transverse
A5: Nom du projet :
A7: Identification | F7: Risques | L7: Plan d'action | T7: Probabilité | V7: Gravité | X7: Criticité | Z7: Statut Action
D8: MY SYSTEM
A9: ID_Risque (R+Chrono) | B9: Périmètre | C9: Date de création du risque | D9: Visibilité ROP | E9: Nbre de salariés impactés | F9: Catégorie | G9: Description | H9: Impact potentiel sur le service | I9: Probabilité / Occurrence | J9: Gravité | K9: Criticité | L9: Actions | M9: Responsable de l'action | N9: Date cible | O9: Statut des actions liées au risque | P9: Date de clôture | Q9: Efficacité action (en %) | R9: Commentaires | T9: Appréciation | U9: Note | V9: Appréciation | W9: Note | X9: 5 | Y9: Faible
A10: R001 | B10: Projet A | C10: 44678 | D10: Non | E10: 2 | F10: Technique | G10: Connaissances de l'application | H10: Retard de livraison | I10: Faible | J10: Très forte | K10: =(IF(Tableau3[[#This Row],[Probabilité / Occurrence]]="","",VLOOKUP((VLOOKUP(Tableau3[[#This Row],[Probabilité / Occurrence]],$T$10:$U$13,2,FALSE)*(VLOOKUP(Tableau3[[#This Row],[Gravité]],$V$10:$W$13,2,FALSE))),$X$9:$Y$23,2,FALSE))) -> Moyenne | L10: Mise à jour des procédures et documentation projet | M10: XXXX | N10: 44752 | O10: Close | P10: 44824 | Q10: 0.9 | T10: Faible | U10: 1 | V10: Faible | W10: 5 | X10: 6 | Y10: Faible | Z10: Non applicable
A11: R002 | B11: Projet B | C11: 44678 | D11: Non | E11: 3 | F11: Ressources Humaines | G11: Départ de XXXX | I11: Moyenne | J11: Faible | K11: =(IF(Tableau3[[#This Row],[Probabilité / Occurrence]]="","",VLOOKUP((VLOOKUP(Tableau3[[#This Row],[Probabilité / Occurrence]],$T$10:$U$13,2,FALSE)*(VLOOKUP(Tableau3[[#This Row],[Gravité]],$V$10:$W$13,2,FALSE))),$X$9:$Y$23,2,FALSE))) -> Faible | T11: Moyenne | U11: 2 | V11: Moyenne | W11: 6 | X11: 7 | Y11: Faible | Z11: A traiter
A12: R003 | B12: Projet A | C12: 44678 | D12: Non | E12: 10 | F12: Technique | G12: Instabilité des données source | I12: Faible | J12: Faible | K12: =(IF(Tableau3[[#This Row],[Probabilité / Occurrence]]="","",VLOOKUP((VLOOKUP(Tableau3[[#This Row],[Probabilité / Occurrence]],$T$10:$U$13,2,FALSE)*(VLOOKUP(Tableau3[[#This Row],[Gravité]],$V$10:$W$13,2,FALSE))),$X$9:$Y$23,2,FALSE))) -> Faible | T12: Forte | U12: 3 | V12: Forte | W12: 7 | X12: 8 | Y12: Moyenne | Z12: En cours
A13: R004 | B13: Projet C | C13: 44696 | D13: Oui | E13: 5 | F13: Technique | G13: Choix techniques | I13: Moyenne | J13: Faible | K13: =(IF(Tableau3[[#This Row],[Probabilité / Occurrence]]="","",VLOOKUP((VLOOKUP(Tableau3[[#This Row],[Probabilité / Occurrence]],$T$10:$U$13,2,FALSE)*(VLOOKUP(Tableau3[[#This Row],[Gravité]],$V$10:$W$13,2,FALSE))),$X$9:$Y$23,2,FALSE))) -> Faible | T13: Très forte | U13: 4 | V13: Très forte | W13: 8 | X13: 10 | Y13: Faible | Z13: Suspendue
A14: R005 | B14: Projet C | C14: 44698 | D14: Oui | E14: 24 | F14: Qualité | G14: Implication/niveau technique ressource sur le projet | I14: Très forte | J14: Forte | K14: =(IF(Tableau3[[#This Row],[Probabilité / Occurrence]]="","",VLOOKUP((VLOOKUP(Tableau3[[#This Row],[Probabilité / Occurrence]],$T$10:$U$13,2,FALSE)*(VLOOKUP(Tableau3[[#This Row],[Gravité]],$V$10:$W$13,2,FALSE))),$X$9:$Y$23,2,FALSE))) -> Très forte | X14: 12 | Y14: Moyenne | Z14: Annulée
A15: R006 | B15: Projet B | C15: 44687 | D15: Oui | E15: 35 | F15: Ressources Humaines | G15: Sur-charge XXXX | I15: Forte | J15: Très forte | K15: =(IF(Tableau3[[#This Row],[Probabilité / Occurrence]]="","",VLOOKUP((VLOOKUP(Tableau3[[#This Row],[Probabilité / Occurrence]],$T$10:$U$13,2,FALSE)*(VLOOKUP(Tableau3[[#This Row],[Gravité]],$V$10:$W$13,2,FALSE))),$X$9:$Y$23,2,FALSE))) -> Forte | X15: 14 | Y15: Moyenne | Z15: Close
A16: R007 | B16: Projet D | C16: 44727 | D16: Oui | E16: 1 | F16: Qualité | G16: Temps de réponse client et investissement client | I16: Très forte | J16: Moyenne | K16: =(IF(Tableau3[[#This Row],[Probabilité / Occurrence]]="","",VLOOKUP((VLOOKUP(Tableau3[[#This Row],[Probabilité / Occurrence]],$T$10:$U$13,2,FALSE)*(VLOOKUP(Tableau3[[#This Row],[Gravité]],$V$10:$W$13,2,FALSE))),$X$9:$Y$23,2,FALSE))) -> Forte | X16: 15 | Y16: Moyenne
A17: R008 | B17: Projet D | C17: 44727 | D17: Oui | E17: 3 | F17: Ressources Humaines | G17: Disponibilité XXXX | I17: Forte | J17: Forte | K17: =(IF(Tableau3[[#This Row],[Probabilité / Occurrence]]="","",VLOOKUP((VLOOKUP(Tableau3[[#This Row],[Probabilité / Occurrence]],$T$10:$U$13,2,FALSE)*(VLOOKUP(Tableau3[[#This Row],[Gravité]],$V$10:$W$13,2,FALSE))),$X$9:$Y$23,2,FALSE))) -> Forte | X17: 16 | Y17: Moyenne
A18: R011 | B18: Projet D | C18: 44727 | D18: Oui | E18: 2 | F18: Ressources Humaines | G18: Départ XXXX | I18: Moyenne | J18: Moyenne | K18: =(IF(Tableau3[[#This Row],[Probabilité / Occurrence]]="","",VLOOKUP((VLOOKUP(Tableau3[[#This Row],[Probabilité / Occurrence]],$T$10:$U$13,2,FALSE)*(VLOOKUP(Tableau3[[#This Row],[Gravité]],$V$10:$W$13,2,FALSE))),$X$9:$Y$23,2,FALSE))) -> Moyenne | X18: 18 | Y18: Forte
A19: R014 | B19: Projet E | C19: 44752 | D19: Oui | E19: 5 | F19: Ressources Humaines | G19: Documentation technique à terminer | I19: Faible | J19: Moyenne | K19: =(IF(Tableau3[[#This Row],[Probabilité / Occurrence]]="","",VLOOKUP((VLOOKUP(Tableau3[[#This Row],[Probabilité / Occurrence]],$T$10:$U$13,2,FALSE)*(VLOOKUP(Tableau3[[#This Row],[Gravité]],$V$10:$W$13,2,FALSE))),$X$9:$Y$23,2,FALSE))) -> Faible | X19: 20 | Y19: Moyenne
A20: R015 | B20: Projet E | C20: 44762 | D20: Oui | E20: 9 | F20: Commercial | G20: Relation client uniquement sur XXXX | I20: Moyenne | J20: Très forte | K20: =(IF(Tableau3[[#This Row],[Probabilité / Occurrence]]="","",VLOOKUP((VLOOKUP(Tableau3[[#This Row],[Probabilité / Occurrence]],$T$10:$U$13,2,FALSE)*(VLOOKUP(Tableau3[[#This Row],[Gravité]],$V$10:$W$13,2,FALSE))),$X$9:$Y$23,2,FALSE))) -> Moyenne | X20: 21 | Y20: Forte
A21: R016 | B21: Projet E | C21: 44767 | D21: Oui | E21: 6 | F21: Technique | G21: Risque de perte documentaire en cas de panne du NAS | I21: Faible | J21: Faible | K21: =(IF(Tableau3[[#This Row],[Probabilité / Occurrence]]="","",VLOOKUP((VLOOKUP(Tableau3[[#This Row],[Probabilité / Occurrence]],$T$10:$U$13,2,FALSE)*(VLOOKUP(Tableau3[[#This Row],[Gravité]],$V$10:$W$13,2,FALSE))),$X$9:$Y$23,2,FALSE))) -> Faible | X21: 24 | Y21: Forte
A22: R017 | B22: Projet ski | C22: 46070 | F22: Technique | G22: Attaque ddos | I22: Moyenne | J22: Forte | K22: =(IF(Tableau3[[#This Row],[Probabilité / Occurrence]]="","",VLOOKUP((VLOOKUP(Tableau3[[#This Row],[Probabilité / Occurrence]],$T$10:$U$13,2,FALSE)*(VLOOKUP(Tableau3[[#This Row],[Gravité]],$V$10:$W$13,2,FALSE))),$X$9:$Y$23,2,FALSE))) -> Moyenne | X22: 28 | Y22: Très forte
A23: R018 | B23: Projet ski | C23: 46070 | F23: Technique | G23: perte de données | I23: Moyenne | J23: Forte | K23: =(IF(Tableau3[[#This Row],[Probabilité / Occurrence]]="","",VLOOKUP((VLOOKUP(Tableau3[[#This Row],[Probabilité / Occurrence]],$T$10:$U$13,2,FALSE)*(VLOOKUP(Tableau3[[#This Row],[Gravité]],$V$10:$W$13,2,FALSE))),$X$9:$Y$23,2,FALSE))) -> Moyenne | X23: 32 | Y23: Très forte
A24: R019 | B24: Projet ski | C24: 46070 | F24: Infrastructure | G24: incendie | I24: Faible | J24: Très forte | K24: =(IF(Tableau3[[#This Row],[Probabilité / Occurrence]]="","",VLOOKUP((VLOOKUP(Tableau3[[#This Row],[Probabilité / Occurrence]],$T$10:$U$13,2,FALSE)*(VLOOKUP(Tableau3[[#This Row],[Gravité]],$V$10:$W$13,2,FALSE))),$X$9:$Y$23,2,FALSE))) -> Moyenne
A25: R020 | B25: Green It Inventory | C25: 46071 | F25: Technique | G25: Retard dans le développement (Tom junior) | H25: Rallentissement de la progression | I25: Forte | J25: Très forte | K25: =(IF(Tableau3[[#This Row],[Probabilité / Occurrence]]="","",VLOOKUP((VLOOKUP(Tableau3[[#This Row],[Probabilité / Occurrence]],$T$10:$U$13,2,FALSE)*(VLOOKUP(Tableau3[[#This Row],[Gravité]],$V$10:$W$13,2,FALSE))),$X$9:$Y$23,2,FALSE))) -> Forte | L25: Former Tom en amont (tutoriels AWS) | M25: chef de projet | N25: 46057 | O25: Close | P25: 46071 | Q25: 1
A26: R021 | B26: Green It Inventory | C26: 46071 | F26: Commercial | G26: Dépassement budget | H26: Retard de livraison | I26: Moyenne | J26: Forte | K26: =(IF(Tableau3[[#This Row],[Probabilité / Occurrence]]="","",VLOOKUP((VLOOKUP(Tableau3[[#This Row],[Probabilité / Occurrence]],$T$10:$U$13,2,FALSE)*(VLOOKUP(Tableau3[[#This Row],[Gravité]],$V$10:$W$13,2,FALSE))),$X$9:$Y$23,2,FALSE))) -> Moyenne | L26: Prioriser le MVP fonctionnel en prod, pas d'ajout de features | M26: developpeurs | N26: 46071 | O26: En cours
A27: R022 | B27: Green It Inventory | C27: 46071 | F27: Commercial | G27: Concurrence d’un géant du Cloud | H27: Déclin des utilisateurs | I27: Forte | J27: Très forte | K27: =(IF(Tableau3[[#This Row],[Probabilité / Occurrence]]="","",VLOOKUP((VLOOKUP(Tableau3[[#This Row],[Probabilité / Occurrence]],$T$10:$U$13,2,FALSE)*(VLOOKUP(Tableau3[[#This Row],[Gravité]],$V$10:$W$13,2,FALSE))),$X$9:$Y$23,2,FALSE))) -> Forte | L27: Faire valoir la simplicité et le prix - Promouvoir made in france - Normes ISO à jour | M27: marketing et expert carbone | N27: 46071 | O27: En cours
K28: =(IF(Tableau3[[#This Row],[Probabilité / Occurrence]]="","",VLOOKUP((VLOOKUP(Tableau3[[#This Row],[Probabilité / Occurrence]],$T$10:$U$13,2,FALSE)*(VLOOKUP(Tableau3[[#This Row],[Gravité]],$V$10:$W$13,2,FALSE))),$X$9:$Y$23,2,FALSE)))
K29: =(IF(Tableau3[[#This Row],[Probabilité / Occurrence]]="","",VLOOKUP((VLOOKUP(Tableau3[[#This Row],[Probabilité / Occurrence]],$T$10:$U$13,2,FALSE)*(VLOOKUP(Tableau3[[#This Row],[Gravité]],$V$10:$W$13,2,FALSE))),$X$9:$Y$23,2,FALSE)))
K30: =(IF(Tableau3[[#This Row],[Probabilité / Occurrence]]="","",VLOOKUP((VLOOKUP(Tableau3[[#This Row],[Probabilité / Occurrence]],$T$10:$U$13,2,FALSE)*(VLOOKUP(Tableau3[[#This Row],[Gravité]],$V$10:$W$13,2,FALSE))),$X$9:$Y$23,2,FALSE)))
K31: =(IF(Tableau3[[#This Row],[Probabilité / Occurrence]]="","",VLOOKUP((VLOOKUP(Tableau3[[#This Row],[Probabilité / Occurrence]],$T$10:$U$13,2,FALSE)*(VLOOKUP(Tableau3[[#This Row],[Gravité]],$V$10:$W$13,2,FALSE))),$X$9:$Y$23,2,FALSE)))
K32: =(IF(Tableau3[[#This Row],[Probabilité / Occurrence]]="","",VLOOKUP((VLOOKUP(Tableau3[[#This Row],[Probabilité / Occurrence]],$T$10:$U$13,2,FALSE)*(VLOOKUP(Tableau3[[#This Row],[Gravité]],$V$10:$W$13,2,FALSE))),$X$9:$Y$23,2,FALSE)))
K33: =(IF(Tableau3[[#This Row],[Probabilité / Occurrence]]="","",VLOOKUP((VLOOKUP(Tableau3[[#This Row],[Probabilité / Occurrence]],$T$10:$U$13,2,FALSE)*(VLOOKUP(Tableau3[[#This Row],[Gravité]],$V$10:$W$13,2,FALSE))),$X$9:$Y$23,2,FALSE)))
K34: =(IF(Tableau3[[#This Row],[Probabilité / Occurrence]]="","",VLOOKUP((VLOOKUP(Tableau3[[#This Row],[Probabilité / Occurrence]],$T$10:$U$13,2,FALSE)*(VLOOKUP(Tableau3[[#This Row],[Gravité]],$V$10:$W$13,2,FALSE))),$X$9:$Y$23,2,FALSE)))
K35: =(IF(Tableau3[[#This Row],[Probabilité / Occurrence]]="","",VLOOKUP((VLOOKUP(Tableau3[[#This Row],[Probabilité / Occurrence]],$T$10:$U$13,2,FALSE)*(VLOOKUP(Tableau3[[#This Row],[Gravité]],$V$10:$W$13,2,FALSE))),$X$9:$Y$23,2,FALSE)))
K36: =(IF(Tableau3[[#This Row],[Probabilité / Occurrence]]="","",VLOOKUP((VLOOKUP(Tableau3[[#This Row],[Probabilité / Occurrence]],$T$10:$U$13,2,FALSE)*(VLOOKUP(Tableau3[[#This Row],[Gravité]],$V$10:$W$13,2,FALSE))),$X$9:$Y$23,2,FALSE)))
K37: =(IF(Tableau3[[#This Row],[Probabilité / Occurrence]]="","",VLOOKUP((VLOOKUP(Tableau3[[#This Row],[Probabilité / Occurrence]],$T$10:$U$13,2,FALSE)*(VLOOKUP(Tableau3[[#This Row],[Gravité]],$V$10:$W$13,2,FALSE))),$X$9:$Y$23,2,FALSE)))
K38: =(IF(Tableau3[[#This Row],[Probabilité / Occurrence]]="","",VLOOKUP((VLOOKUP(Tableau3[[#This Row],[Probabilité / Occurrence]],$T$10:$U$13,2,FALSE)*(VLOOKUP(Tableau3[[#This Row],[Gravité]],$V$10:$W$13,2,FALSE))),$X$9:$Y$23,2,FALSE)))

Sheet AMDEC
Z1: ="0 - "&AE1 -> 0 - 249 | AB1: FAIBLE | AE1: 249 | AF1: 1
B2: Analyse de risque pour le processus | Z2: =(AE1+1)&" - "&AE2 -> 250 - 499 | AB2: MEDIUM | AE2: 499 | AF2: 2
B4: Nom du projet / processus / service : | D4: Preparé par: | Z4: =(AE2+1)&" - "&AE4 -> 500 - 749 | AB4: HAUT | AE4: 749 | AF4: 3
D5: Date (Orig): | F5: (Rev.): 1 | Z5: =(AE4+1)&" - "&AE5 -> 750 - 1000 | AB5: TRES HAUT | AE5: 1000 | AF5: 4
AF6: 5
B7: Identification des défaillances | G7: Gravité /Severity | I7: Occurrence | K7: Detectabilité | M7: Evaluation | O7: Atténuation | R7: Valeur attendue si action efficace | X7: Re-évaluation après action | AC7: Niveau de risque | AF7: 6
B8: ID Action | C8: Activité de Management | D8: Mode d'échec potentiel Description du risque | E8: Date d'Identification | F8: Origine | G8: Effets potentiels de défaillance | H8: SEV | I8: Causes potentiel | J8: OCC | K8: Contrôles de processus actuels | L8: DET | M8: CRI | N8: RPN | O8: Actions recommandées | P8: Resp | Q8: Target date | R8: SEV | S8: OCC | T8: DET | U8: CRI | V8: RPN | W8: Actions prises | X8: SEV | Y8: OCC | Z8: DET | AA8: CRI | AB8: RPN | AC8: Niveau en cours | AD8: Niveau Initiale | AE8: Commentaires | AF8: 7
C9: Quelle est l'étape de management ? | D9: Identifier toutes les pannes possibles - Un échec peut être dupliqué si plusieurs effets et/ou si plusieurs causes pour un même effet. | E9: Date d'identification du risque | F9: Comment le risque a-t-il été identifié ? Origine de l'identification du risque. Par exemple retour d'expérience, analyse de cahier des charges… | G9: Quel est l'impact sur les variables de sortie clés (exigences du client) ou les exigences internes ? - Un impact par ligne | H9: Quelle est la gravité de l'effet au client? | I9: « Qu'est-ce qui fait que la saisie de la clé se passe mal ? (Comment le mode de défaillance peut-il se produire ?) Une cause potentielle par ligne. Brainstorming sur les causes : - homme - Matériel - méthode -machine - environnement Déterminer les causes profondes | J9: Quelle est la fréquence de la cause susceptible de se produire ? | K9: Quels sont les contrôles existants qui empêchent le mode de défaillance de se produire ou le détecter s'il se produit ? Tous les moyens de contrôle correspondant à une même cause potentielle sont dans la même cellule. Détecter: - Chèques - Essais planifiés - KPI Prévention: - Commentaires | L9: Quelle est la probabilité Détection de la cause ? | M9: Criticité ? | N9: Priorité de risque # à classer | O9: Quelles sont les actions pour réduire l'Occurrence de la cause, ou améliorer la Détection ? Les actions doivent : - éliminer l'échec SEV = 9/10 - Éliminer les causes affectant directement le résultat du processus - réduire l'occurrence - Améliorer la détection des tests à la dernière option. | P9: Qui est responsable de l'action recommandée ? (Un seul responsable) | Q9: Date d'achèvement de l'action souhaitée | R9: Quelle est la gravité de l'effet au client? | S9: Quelle est la fréquence de la cause susceptible de se produire ? | T9: Quelle est la probabilité Détection de la cause ? | U9: Criticité ? | W9: Quelles ont été les actions mises en place ? Inclure le mois/année d'achèvement. (Ensuite, recalculez le RPN résultant.) | X9: Quelle est la gravité de l'effet au client? | Y9: Quelle est la fréquence de la cause susceptible de se produire ? | Z9: Quelle est la probabilité Détection de la cause ? | AA9: Criticité ? | AC9: Niveau en cours | AD9: Niveau de 1ère évaluation | AF9: 8
H10: Voir la fiche Facteurs de notation. | J10: Voir la fiche Facteurs de notation. | L10: Voir la fiche Facteurs de notation. | AF10: 9
B11: 1 | C11: planification | D11: indisponibilité du service | E11: 46070 | F11: attaque ddos | G11: important | H11: 6 | I11: homme | J11: 5 | K11: limiter les connexions simultanées, file d'attente, cloudflare, captchas, etc | L11: 2 | M11: =IF(H11+J11=0," ",H11*J11) -> 30 | N11: =IF(H11+J11+L11=0,"-",H11*J11*L11) -> 60 | O11: utliser une solution contre le ddos | P11: responsable cyber-securité | R11: 1 | S11: 5 | T11: 5 | U11: =IF(R11+S11=0," ",R11*S11) -> 5 | V11: =IF(R11+S11+T11=0,"-",R11*S11*T11) -> 25 | AA11: =IF(X11+Y11=0," ",X11*Y11) | AB11: =IF(X11+Y11+Z11=0,"-",X11*Y11*Z11) -> - | AC11: =IF(AB11="-",AD11,IF(AB11>$AE$4,"Very High",IF(AB11>$AE$2,"High",IF(AB11>$AE$1,"Medium",IF(AB11>0,"Low",""))))) -> Low | AD11: =IF(N11="-","-",IF(N11>$AE$4,"Very High",IF(N11>$AE$2,"High",IF(N11>$AE$1,"Medium",IF(N11>0,"Low",""))))) -> Low | AF11: 10
B12: 2 | C12: planification | D12: perte de données client, produit | E12: 46070 | F12: perte de données | G12: critique | H12: 9 | I12: matérielle | J12: 2 | K12: automatisation des sauvegardes, stockage cloud | L12: 5 | M12: =IF(H12+J12=0," ",H12*J12) -> 18 | N12: =IF(H12+J12+L12=0,"-",H12*J12*L12) -> 90 | O12: généraliser les tests,système de log | P12: chef de projet | R12: 9 | S12: 2 | T12: 5 | U12: =IF(R12+S12=0," ",R12*S12) -> 18 | V12: =IF(R12+S12+T12=0,"-",R12*S12*T12) -> 90 | AA12: =IF(X12+Y12=0," ",X12*Y12) | AB12: =IF(X12+Y12+Z12=0,"-",X12*Y12*Z12) -> - | AC12: =IF(AB12="-",AD12,IF(AB12>$AE$4,"Very High",IF(AB12>$AE$2,"High",IF(AB12>$AE$1,"Medium",IF(AB12>0,"Low",""))))) -> Low | AD12: =IF(N12="-","-",IF(N12>$AE$4,"Very High",IF(N12>$AE$2,"High",IF(N12>$AE$1,"Medium",IF(N12>0,"Low",""))))) -> Low
B13: 3 | C13: planification | D13: destruction de matériel, dommages corporels | E13: 46070 | F13: alarme incendie, odeurs, alerte d'employés | G13: Dangereux | H13: 10 | I13: matériel, humain, environnemental | J13: 2 | K13: alarme incendie, prévention, inspection du matériel | L13: 4 | M13: =IF(H13+J13=0," ",H13*J13) -> 20 | N13: =IF(H13+J13+L13=0,"-",H13*J13*L13) -> 80 | O13: installation d'extincteur automatiques, plan d'évacuation | P13: PDG | R13: 8 | S13: 2 | T13: 3 | U13: =IF(R13+S13=0," ",R13*S13) -> 16 | V13: =IF(R13+S13+T13=0,"-",R13*S13*T13) -> 48 | AA13: =IF(X13+Y13=0," ",X13*Y13) | AB13: =IF(X13+Y13+Z13=0,"-",X13*Y13*Z13) -> - | AC13: =IF(AB13="-",AD13,IF(AB13>$AE$4,"Very High",IF(AB13>$AE$2,"High",IF(AB13>$AE$1,"Medium",IF(AB13>0,"Low",""))))) -> Low | AD13: =IF(N13="-","-",IF(N13>$AE$4,"Very High",IF(N13>$AE$2,"High",IF(N13>$AE$1,"Medium",IF(N13>0,"Low",""))))) -> Low
M14: =IF(H14+J14=0," ",H14*J14) | N14: =IF(H14+J14+L14=0,"-",H14*J14*L14) -> - | U14: =IF(R14+S14=0," ",R14*S14) | V14: =IF(R14+S14+T14=0,"-",R14*S14*T14) -> - | AA14: =IF(X14+Y14=0," ",X14*Y14) | AB14: =IF(X14+Y14+Z14=0,"-",X14*Y14*Z14) -> - | AC14: =IF(AB14="-",AD14,IF(AB14>$AE$4,"Very High",IF(AB14>$AE$2,"High",IF(AB14>$AE$1,"Medium",IF(AB14>0,"Low",""))))) -> - | AD14: =IF(N14="-","-",IF(N14>$AE$4,"Very High",IF(N14>$AE$2,"High",IF(N14>$AE$1,"Medium",IF(N14>0,"Low",""))))) -> -
M15: =IF(H15+J15=0," ",H15*J15) | N15: =IF(H15+J15+L15=0,"-",H15*J15*L15) -> - | U15: =IF(R15+S15=0," ",R15*S15) | V15: =IF(R15+S15+T15=0,"-",R15*S15*T15) -> - | AA15: =IF(X15+Y15=0," ",X15*Y15) | AB15: =IF(X15+Y15+Z15=0,"-",X15*Y15*Z15) -> - | AC15: =IF(AB15="-",AD15,IF(AB15>$AE$4,"Very High",IF(AB15>$AE$2,"High",IF(AB15>$AE$1,"Medium",IF(AB15>0,"Low",""))))) -> - | AD15: =IF(N15="-","-",IF(N15>$AE$4,"Very High",IF(N15>$AE$2,"High",IF(N15>$AE$1,"Medium",IF(N15>0,"Low",""))))) -> -
M16: =IF(H16+J16=0," ",H16*J16) | N16: =IF(H16+J16+L16=0,"-",H16*J16*L16) -> - | U16: =IF(R16+S16=0," ",R16*S16) | V16: =IF(R16+S16+T16=0,"-",R16*S16*T16) -> - | AA16: =IF(X16+Y16=0," ",X16*Y16) | AB16: =IF(X16+Y16+Z16=0,"-",X16*Y16*Z16) -> - | AC16: =IF(AB16="-",AD16,IF(AB16>$AE$4,"Very High",IF(AB16>$AE$2,"High",IF(AB16>$AE$1,"Medium",IF(AB16>0,"Low",""))))) -> - | AD16: =IF(N16="-","-",IF(N16>$AE$4,"Very High",IF(N16>$AE$2,"High",IF(N16>$AE$1,"Medium",IF(N16>0,"Low",""))))) -> -
M17: =IF(H17+J17=0," ",H17*J17) | N17: =IF(H17+J17+L17=0,"-",H17*J17*L17) -> - | U17: =IF(R17+S17=0," ",R17*S17) | V17: =IF(R17+S17+T17=0,"-",R17*S17*T17) -> - | AA17: =IF(X17+Y17=0," ",X17*Y17) | AB17: =IF(X17+Y17+Z17=0,"-",X17*Y17*Z17) -> - | AC17: =IF(AB17="-",AD17,IF(AB17>$AE$4,"Very High",IF(AB17>$AE$2,"High",IF(AB17>$AE$1,"Medium",IF(AB17>0,"Low",""))))) -> - | AD17: =IF(N17="-","-",IF(N17>$AE$4,"Very High",IF(N17>$AE$2,"High",IF(N17>$AE$1,"Medium",IF(N17>0,"Low",""))))) -> -
M18: =IF(H18+J18=0," ",H18*J18) | N18: =IF(H18+J18+L18=0,"-",H18*J18*L18) -> - | U18: =IF(R18+S18=0," ",R18*S18) | V18: =IF(R18+S18+T18=0,"-",R18*S18*T18) -> - | AA18: =IF(X18+Y18=0," ",X18*Y18) | AB18: =IF(X18+Y18+Z18=0,"-",X18*Y18*Z18) -> - | AC18: =IF(AB18="-",AD18,IF(AB18>$AE$4,"Very High",IF(AB18>$AE$2,"High",IF(AB18>$AE$1,"Medium",IF(AB18>0,"Low",""))))) -> - | AD18: =IF(N18="-","-",IF(N18>$AE$4,"Very High",IF(N18>$AE$2,"High",IF(N18>$AE$1,"Medium",IF(N18>0,"Low",""))))) -> -
M19: =IF(H19+J19=0," ",H19*J19) | N19: =IF(H19+J19+L19=0,"-",H19*J19*L19) -> - | U19: =IF(R19+S19=0," ",R19*S19) | V19: =IF(R19+S19+T19=0,"-",R19*S19*T19) -> - | AA19: =IF(X19+Y19=0," ",X19*Y19) | AB19: =IF(X19+Y19+Z19=0,"-",X19*Y19*Z19) -> - | AC19: =IF(AB19="-",AD19,IF(AB19>$AE$4,"Very High",IF(AB19>$AE$2,"High",IF(AB19>$AE$1,"Medium",IF(AB19>0,"Low",""))))) -> - | AD19: =IF(N19="-","-",IF(N19>$AE$4,"Very High",IF(N19>$AE$2,"High",IF(N19>$AE$1,"Medium",IF(N19>0,"Low",""))))) -> -
M20: =IF(H20+J20=0," ",H20*J20) | N20: =IF(H20+J20+L20=0,"-",H20*J20*L20) -> - | U20: =IF(R20+S20=0," ",R20*S20) | V20: =IF(R20+S20+T20=0,"-",R20*S20*T20) -> - | AA20: =IF(X20+Y20=0," ",X20*Y20) | AB20: =IF(X20+Y20+Z20=0,"-",X20*Y20*Z20) -> - | AC20: =IF(AB20="-",AD20,IF(AB20>$AE$4,"Very High",IF(AB20>$AE$2,"High",IF(AB20>$AE$1,"Medium",IF(AB20>0,"Low",""))))) -> - | AD20: =IF(N20="-","-",IF(N20>$AE$4,"Very High",IF(N20>$AE$2,"High",IF(N20>$AE$1,"Medium",IF(N20>0,"Low",""))))) -> -
M21: =IF(H21+J21=0," ",H21*J21) | N21: =IF(H21+J21+L21=0,"-",H21*J21*L21) -> - | U21: =IF(R21+S21=0," ",R21*S21) | V21: =IF(R21+S21+T21=0,"-",R21*S21*T21) -> - | AA21: =IF(X21+Y21=0," ",X21*Y21) | AB21: =IF(X21+Y21+Z21=0,"-",X21*Y21*Z21) -> - | AC21: =IF(AB21="-",AD21,IF(AB21>$AE$4,"Very High",IF(AB21>$AE$2,"High",IF(AB21>$AE$1,"Medium",IF(AB21>0,"Low",""))))) -> - | AD21: =IF(N21="-","-",IF(N21>$AE$4,"Very High",IF(N21>$AE$2,"High",IF(N21>$AE$1,"Medium",IF(N21>0,"Low",""))))) -> -
M22: =IF(H22+J22=0," ",H22*J22) | N22: =IF(H22+J22+L22=0,"-",H22*J22*L22) -> - | U22: =IF(R22+S22=0," ",R22*S22) | V22: =IF(R22+S22+T22=0,"-",R22*S22*T22) -> - | AA22: =IF(X22+Y22=0," ",X22*Y22) | AB22: =IF(X22+Y22+Z22=0,"-",X22*Y22*Z22) -> - | AC22: =IF(AB22="-",AD22,IF(AB22>$AE$4,"Very High",IF(AB22>$AE$2,"High",IF(AB22>$AE$1,"Medium",IF(AB22>0,"Low",""))))) -> - | AD22: =IF(N22="-","-",IF(N22>$AE$4,"Very High",IF(N22>$AE$2,"High",IF(N22>$AE$1,"Medium",IF(N22>0,"Low",""))))) -> -
M23: =IF(H23+J23=0," ",H23*J23) | N23: =IF(H23+J23+L23=0,"-",H23*J23*L23) -> - | U23: =IF(R23+S23=0," ",R23*S23) | V23: =IF(R23+S23+T23=0,"-",R23*S23*T23) -> - | AA23: =IF(X23+Y23=0," ",X23*Y23) | AB23: =IF(X23+Y23+Z23=0,"-",X23*Y23*Z23) -> - | AC23: =IF(AB23="-",AD23,IF(AB23>$AE$4,"Very High",IF(AB23>$AE$2,"High",IF(AB23>$AE$1,"Medium",IF(AB23>0,"Low",""))))) -> - | AD23: =IF(N23="-","-",IF(N23>$AE$4,"Very High",IF(N23>$AE$2,"High",IF(N23>$AE$1,"Medium",IF(N23>0,"Low",""))))) -> -
M24: =IF(H24+J24=0," ",H24*J24) | N24: =IF(H24+J24+L24=0,"-",H24*J24*L24) -> - | U24: =IF(R24+S24=0," ",R24*S24) | V24: =IF(R24+S24+T24=0,"-",R24*S24*T24) -> - | AA24: =IF(X24+Y24=0," ",X24*Y24) | AB24: =IF(X24+Y24+Z24=0,"-",X24*Y24*Z24) -> - | AC24: =IF(AB24="-",AD24,IF(AB24>$AE$4,"Very High",IF(AB24>$AE$2,"High",IF(AB24>$AE$1,"Medium",IF(AB24>0,"Low",""))))) -> - | AD24: =IF(N24="-","-",IF(N24>$AE$4,"Very High",IF(N24>$AE$2,"High",IF(N24>$AE$1,"Medium",IF(N24>0,"Low",""))))) -> -
M25: =IF(H25+J25=0," ",H25*J25) | N25: =IF(H25+J25+L25=0,"-",H25*J25*L25) -> - | U25: =IF(R25+S25=0," ",R25*S25) | V25: =IF(R25+S25+T25=0,"-",R25*S25*T25) -> - | AA25: =IF(X25+Y25=0," ",X25*Y25) | AB25: =IF(X25+Y25+Z25=0,"-",X25*Y25*Z25) -> - | AC25: =IF(AB25="-",AD25,IF(AB25>$AE$4,"Very High",IF(AB25>$AE$2,"High",IF(AB25>$AE$1,"Medium",IF(AB25>0,"Low",""))))) -> - | AD25: =IF(N25="-","-",IF(N25>$AE$4,"Very High",IF(N25>$AE$2,"High",IF(N25>$AE$1,"Medium",IF(N25>0,"Low",""))))) -> -
... M38: =IF(H38+J38=0," ",H38*J38) | N38: =IF(H38+J38+L38=0,"-",H38*J38*L38) -> - | U38: =IF(R38+S38=0," ",R38*S38) | V38: =IF(R38+S38+T38=0,"-",R38*S38*T38) -> - | AA38: =IF(X38+Y38=0," ",X38*Y38) | AB38: =IF(X38+Y38+Z38=0,"-",X38*Y38*Z38) -> - | AC38: =IF(AB38="-",AD38,IF(AB38>$AE$4,"Very High",IF(AB38>$AE$2,"High",IF(AB38>$AE$1,"Medium",IF(AB38>0,"Low",""))))) -> - | AD38: =IF(N38="-","-",IF(N38>$AE$4,"Very High",IF(N38>$AE$2,"High",IF(N38>$AE$1,"Medium",IF(N38>0,"Low",""))))) -> -

Sheet Facteurs de notation (AMDEC)
B2: AMDEC/FMEA - grille de notation
B3: Choisissez l'échelle la plus adaptée à votre contexte. L'échelle de fréquence peut être adaptée à votre contexte.
B5: ÉVAL. | C5: DEGRÉ DE GRAVITÉ (SEV) | E5: PROBABILITÉ D'OCCURRENCE (OCC) | G5: CAPACITÉ À DÉTECTER (DET)
B6: 1 | C6: Rien | D6: L'échec ne serait pas perceptible pour le client et n'affecterait pas le processus ou le produit du client. | E6: Isolé : l'échec est peu probable. | F6: Une occurrence sur plus de cinq ans ou moins de deux occurrences sur un milliard d'événements (Cpk > 2,00). | G6: Presque certain | H6: Le défaut est évident ou il y a une inspection 100% automatique avec un étalonnage régulier et une maintenance préventive de l'équipement d'inspection.
B7: 2 | C7: Mineur | D7: Une défaillance peut ne pas être évidente pour le client, mais aurait des effets mineurs sur le processus ou le produit du client. | E7: Faible : les échecs sont rares. | F7: Une occurrence tous les trois à cinq ans ou 2 occurrences dans un milliard d'événements (Cpk ≈ 2,00). | G7: Très haut | H7: Tous les produits sont inspectés à 100% automatiquement.
B8: 3 | C8: Très limité | D8: L'échec créerait une nuisance mineure pour le client, mais le client peut la surmonter sans perte de performance. | E8: Faible : relativement peu d'échecs. | F8: Une occurrence tous les un à trois ans ou six occurrences sur dix millions d'événements (Cpk 1,67). | G8: Haute | H8: Un programme SPC efficace est en place avec des capacités de processus (Cpk) supérieures à 1,33.
B9: 4 | C9: Modérer | D9: Insatisfaction du client en raison de performances réduites. L'échec peut être surmonté par des modifications du processus ou du produit du client, mais il y a une perte de performance mineure. | E9: Modérément faible : pannes peu fréquentes. | F9: Une occurrence par an ou six occurrences sur 100 000 événements (Cpk ≈ 1,33). | G9: Modérément élevé | H9: La SPC est utilisée et il y a une réaction immédiate aux conditions hors de contrôle.
B10: 5 | C10: Limité | D10: Le client est mal à l'aise ou sa productivité est réduite par la dégradation continue de l'effet. L'échec crée une perte de performance suffisante pour amener le client à se plaindre. | E10: Modéré : échecs occasionnels. | F10: Une occurrence tous les six mois à un an ou cinq occurrences sur 10 000 événements (Cpk ≈ 1,17). | G10: Modérer | H10: Un certain contrôle statistique des processus (SPC) est utilisé dans le processus et le produit est inspecté hors ligne.
B11: 6 | C11: Important | D11: Réparation sous garantie, temps d'arrêt ou réclamation importante de fabrication ou d'assemblage. Une défaillance entraîne un sous-système ou un dysfonctionnement partiel du produit. | E11: Modérément élevé : Défaillances fréquentes. | F11: Une occurrence tous les trois mois ou trois occurrences sur 1 000 événements (Cpk ≈ 1,00). | G11: Meugler | H11: Le produit est inspecté à 100 % manuellement à l'aide de jauges go/no-go ou d'autres jauges anti-erreur.
B12: 7 | C12: Hautement significatif | D12: Haut degré d'insatisfaction du client en raison d'une défaillance des composants sans perte complète de fonction. Productivité impactée par des niveaux élevés de rebut ou de reprise. | E12: Élevé : les échecs se produisent souvent. | F12: Une occurrence tous les mois ou une occurrence sur 100 événements (Cpk ≈ 0,83). | G12: Très lent | H12: Le produit est inspecté à 100% manuellement dans le processus.
B13: 8 | C13: Majeur | D13: Une panne rend l'unité inutilisable ou impropre à l'utilisation. Très haut degré d'insatisfaction en raison de la perte de fonction sans impact négatif sur la sécurité ou les réglementations gouvernementales | E13: Élevé : échecs répétés. | F13: Une occurrence par semaine ou une probabilité de 5 occurrences sur 100 événements (Cpk ≈ 0,67). | G13: À distance | H13: Le produit est accepté sur la base de l'absence de défauts dans un échantillon.
B14: 9 | C14: Critique / Dangereux avec avertissement | D14: Client mis en danger en raison de l'effet négatif sur les performances du système de sécurité avec avertissement avant défaillance ou violation des réglementations gouvernementales | E14: Élevé : les échecs se produisent presque aussi souvent qu'autrement. | F14: Une occurrence tous les trois à quatre jours ou une probabilité de trois occurrences sur 10 événements (Cpk 0,33). | G14: Très éloigné | H14: Le produit est échantillonné, inspecté et libéré sur la base de plans d'échantillonnage de niveau de qualité acceptable (NQA).
B15: 10 | C15: Inacceptable / Dangereux sans avertissement | D15: Le client est en danger en raison de l'effet négatif sur les performances sûres du système sans avertissement avant une défaillance ou une violation des réglementations gouvernementales. Une défaillance pourrait blesser le client ou un employé. | E15: Très élevé : L'échec est presque inévitable. | F15: Plus d'une occurrence par jour ou une probabilité de plus de trois occurrences sur 10 événements (Cpk < 0,33). | G15: Incertitude absolue | H15: Le produit n'est pas inspecté ou le défaut causé par la défaillance n'est pas détectable.

Sheet Produit
Z1: RPN Colours | AE1: Limits | AF1: RF Scale
C2: Design Risk Analysis | T2: ="0 - "&Y2 -> 0 - | Z2: ="0 - "&AE2 -> 0 - 249 | AB2: LOW | AE2: 249 | AF2: 1
T3: =(Y2+1)&" - "&Y3 -> 1 - | Z3: =(AE2+1)&" - "&AE3 -> 250 - 499 | AB3: MEDIUM | AE3: 499 | AF3: 2
C4: Process Name: | G4: FMEA Team: | K4: Prepared by: | T4: =(Y3+1)&" - "&Y4 -> 1 - | Z4: =(AE3+1)&" - "&AE4 -> 500 - 749 | AB4: HIGH | AE4: 749 | AF4: 3
K5: FMEA Date (Orig): | O5: (Rev.): | T5: =(Y4+1)&" - "&Y5 -> 1 - | Z5: =(AE4+1)&" - "&AE5 -> 750 - 1000 | AB5: VERY HIGH | AE5: 1000 | AF5: 4
AF6: 5
AF7: 6
AF8: 7
AF9: 8
AF10: 9
AF11: 10
C12: Failure identification | G12: Severity | I12: Occurrence | K12: Detectability | M12: Evaluation | O12: Mitigation | R12: Expected value if action efficient | X12: Re-evaluation after action | AC12: Risks level
A13: ID Action | B13: Component | C13: Product Function | D13: Potential Failure Mode | E13: Identification date | F13: Origin | G13: Potential Failure Effects | H13: SEV | I13: Potential Causes | J13: OCC | K13: Current Process Controls | L13: DET | M13: CRI | N13: RPN | O13: Actions Recommended | P13: Resp | Q13: Target date | R13: SEV | S13: OCC | T13: DET | U13: CRI | V13: RPN | W13: Actions Taken | X13: SEV | Y13: OCC | Z13: DET | AA13: CRI | AB13: RPN | AC13: On going level | AD13: Initial Level
C14: What is the process step? | D14: In what ways can the Component, Subsystem or System potentially fail and cause a safety risk? | E14: Date of identification of the risk | F14: How the risk have been identified? Origin of the identification of the risk. For example return of experience, specification analyse… | G14: What is the impact on Safety? | H14: How Severe is effect on the system? | I14: List every conceivable failure and/or failure mechanism for each failure mode One potential cause per line. Brainstorm causes: - man - material - method - machine - environment Determine root causes | J14: How frequent is cause likely to Occur? | K14: What are the existing controls that either prevent the failure mode from occurring or detect it should it occur? All the control means corresponding to the same potential cause are in the same cell. Detect: - Checks - Planned tests - KPI Prevent: - reviews | L14: How probable is Detection of cause? | M14: Criticity ? | N14: Risk Priority # to rank order concerns | O14: What are the actions for reducing the Occurrence of the cause, or improving Detection? Actions should: - eliminate failure SEV = 9/10 - Eliminate the causes affectinf directly the result of the process - reduce occurrence - Improve test detection at last option. | P14: Who's Responsible for the recommended action? (Only one responsible) | Q14: Date action desired completion | R14: How Severe is effect to the customer? | S14: How frequent is cause likely to Occur? | T14: How probable is Detection of cause? | U14: Criticity ? | W14: What were the actions implemented? Include completion month/year. (Then recalculate resulting RPN.) | X14: How Severe is effect to the customer? | Y14: How frequent is cause likely to Occur? | Z14: How probable is Detection of cause? | AA14: Criticity ? | AC14: Level | AD14: Level of 1st evaluation
H15: See Rating factors sheet. | J15: See Rating factors sheet. | L15: See Rating factors sheet.
A16: D-01 | B16: <Component 1> | C16: <Function 1> | D16: <Potential Failure 1> | H16: 4 | J16: 6 | L16: 5 | M16: =IF(H16+J16=0," ",H16*J16) -> 24 | N16: =IF(H16+J16+L16=0,"-",H16*J16*L16) -> 120 | R16: 4 | S16: 2 | T16: 1 | U16: =IF(R16+S16=0," ",R16*S16) -> 8 | V16: =IF(R16+S16+T16=0,"-",R16*S16*T16) -> 8 | X16: 4 | Y16: 2 | Z16: 1 | AA16: =IF(X16+Y16=0," ",X16*Y16) -> 8 | AB16: =IF(X16+Y16+Z16=0,"-",X16*Y16*Z16) -> 8 | AC16: =IF(AB16="-",AD16,IF(AB16>$AE$4,"Very High",IF(AB16>$AE$3,"High",IF(AB16>$AE$2,"Medium",IF(AB16>0,"Low",""))))) -> Low | AD16: =IF(N16="-","-",IF(N16>$AE$4,"Very High",IF(N16>$AE$3,"High",IF(N16>$AE$2,"Medium",IF(N16>0,"Low",""))))) -> Low
A17: D-02 | D17: <Potential Failure 2> | H17: 1 | J17: 1 | L17: 1 | M17: =IF(H17+J17=0," ",H17*J17) -> 1 | N17: =IF(H17+J17+L17=0,"-",H17*J17*L17) -> 1 | R17: 1 | S17: 1 | T17: 1 | U17: =IF(R17+S17=0," ",R17*S17) -> 1 | V17: =IF(R17+S17+T17=0,"-",R17*S17*T17) -> 1 | X17: 1 | Y17: 1 | Z17: 1 | AA17: =IF(X17+Y17=0," ",X17*Y17) -> 1 | AB17: =IF(X17+Y17+Z17=0,"-",X17*Y17*Z17) -> 1 | AC17: =IF(AB17="-",AD17,IF(AB17>$AE$4,"Very High",IF(AB17>$AE$3,"High",IF(AB17>$AE$2,"Medium",IF(AB17>0,"Low",""))))) -> Low | AD17: =IF(N17="-","-",IF(N17>$AE$4,"Very High",IF(N17>$AE$3,"High",IF(N17>$AE$2,"Medium",IF(N17>0,"Low",""))))) -> Low
A18: D-03 | D18: <Potential Failure 3> | H18: 5 | J18: 5 | L18: 10 | M18: =IF(H18+J18=0," ",H18*J18) -> 25 | N18: =IF(H18+J18+L18=0,"-",H18*J18*L18) -> 250 | R18: 5 | S18: 5 | T18: 2 | U18: =IF(R18+S18=0," ",R18*S18) -> 25 | V18: =IF(R18+S18+T18=0,"-",R18*S18*T18) -> 50 | X18: 5 | Y18: 5 | Z18: 2 | AA18: =IF(X18+Y18=0," ",X18*Y18) -> 25 | AB18: =IF(X18+Y18+Z18=0,"-",X18*Y18*Z18) -> 50 | AC18: =IF(AB18="-",AD18,IF(AB18>$AE$4,"Very High",IF(AB18>$AE$3,"High",IF(AB18>$AE$2,"Medium",IF(AB18>0,"Low",""))))) -> Low | AD18: =IF(N18="-","-",IF(N18>$AE$4,"Very High",IF(N18>$AE$3,"High",IF(N18>$AE$2,"Medium",IF(N18>0,"Low",""))))) -> Medium
A19: D-04 | C19: <Function 2> | D19: <Potential Failure 1> | H19: 7 | J19: 8 | L19: 10 | M19: =IF(H19+J19=0," ",H19*J19) -> 56 | N19: =IF(H19+J19+L19=0,"-",H19*J19*L19) -> 560 | R19: 7 | S19: 8 | T19: 6 | U19: =IF(R19+S19=0," ",R19*S19) -> 56 | V19: =IF(R19+S19+T19=0,"-",R19*S19*T19) -> 336 | X19: 7 | Y19: 8 | Z19: 2 | AA19: =IF(X19+Y19=0," ",X19*Y19) -> 56 | AB19: =IF(X19+Y19+Z19=0,"-",X19*Y19*Z19) -> 112 | AC19: =IF(AB19="-",AD19,IF(AB19>$AE$4,"Very High",IF(AB19>$AE$3,"High",IF(AB19>$AE$2,"Medium",IF(AB19>0,"Low",""))))) -> Low | AD19: =IF(N19="-","-",IF(N19>$AE$4,"Very High",IF(N19>$AE$3,"High",IF(N19>$AE$2,"Medium",IF(N19>0,"Low",""))))) -> High
A20: D-05 | C20: <Function 3> | D20: <Potential Failure 1> | M20: =IF(H20+J20=0," ",H20*J20) | N20: =IF(H20+J20+L20=0,"-",H20*J20*L20) -> - | U20: =IF(R20+S20=0," ",R20*S20) | V20: =IF(R20+S20+T20=0,"-",R20*S20*T20) -> - | AA20: =IF(X20+Y20=0," ",X20*Y20) | AB20: =IF(X20+Y20+Z20=0,"-",X20*Y20*Z20) -> - | AC20: =IF(AB20="-",AD20,IF(AB20>$AE$4,"Very High",IF(AB20>$AE$3,"High",IF(AB20>$AE$2,"Medium",IF(AB20>0,"Low",""))))) -> - | AD20: =IF(N20="-","-",IF(N20>$AE$4,"Very High",IF(N20>$AE$3,"High",IF(N20>$AE$2,"Medium",IF(N20>0,"Low",""))))) -> -
A21: D-06 | D21: <Potential Failure 2> | M21: =IF(H21+J21=0," ",H21*J21) | N21: =IF(H21+J21+L21=0,"-",H21*J21*L21) -> - | U21: =IF(R21+S21=0," ",R21*S21) | V21: =IF(R21+S21+T21=0,"-",R21*S21*T21) -> - | AA21: =IF(X21+Y21=0," ",X21*Y21) | AB21: =IF(X21+Y21+Z21=0,"-",X21*Y21*Z21) -> - | AC21: =IF(AB21="-",AD21,IF(AB21>$AE$4,"Very High",IF(AB21>$AE$3,"High",IF(AB21>$AE$2,"Medium",IF(AB21>0,"Low",""))))) -> - | AD21: =IF(N21="-","-",IF(N21>$AE$4,"Very High",IF(N21>$AE$3,"High",IF(N21>$AE$2,"Medium",IF(N21>0,"Low",""))))) -> -
A22: D-07 | B22: <Component 2> | C22: <Function 1> | D22: <Potential Failure 1> | M22: =IF(H22+J22=0," ",H22*J22) | N22: =IF(H22+J22+L22=0,"-",H22*J22*L22) -> - | U22: =IF(R22+S22=0," ",R22*S22) | V22: =IF(R22+S22+T22=0,"-",R22*S22*T22) -> - | AA22: =IF(X22+Y22=0," ",X22*Y22) | AB22: =IF(X22+Y22+Z22=0,"-",X22*Y22*Z22) -> - | AC22: =IF(AB22="-",AD22,IF(AB22>$AE$4,"Very High",IF(AB22>$AE$3,"High",IF(AB22>$AE$2,"Medium",IF(AB22>0,"Low",""))))) -> - | AD22: =IF(N22="-","-",IF(N22>$AE$4,"Very High",IF(N22>$AE$3,"High",IF(N22>$AE$2,"Medium",IF(N22>0,"Low",""))))) -> -
A23: D-08 | D23: <Potential Failure 2> | M23: =IF(H23+J23=0," ",H23*J23) | N23: =IF(H23+J23+L23=0,"-",H23*J23*L23) -> - | U23: =IF(R23+S23=0," ",R23*S23) | V23: =IF(R23+S23+T23=0,"-",R23*S23*T23) -> - | AA23: =IF(X23+Y23=0," ",X23*Y23) | AB23: =IF(X23+Y23+Z23=0,"-",X23*Y23*Z23) -> - | AC23: =IF(AB23="-",AD23,IF(AB23>$AE$4,"Very High",IF(AB23>$AE$3,"High",IF(AB23>$AE$2,"Medium",IF(AB23>0,"Low",""))))) -> - | AD23: =IF(N23="-","-",IF(N23>$AE$4,"Very High",IF(N23>$AE$3,"High",IF(N23>$AE$2,"Medium",IF(N23>0,"Low",""))))) -> -
A24: D-09 | D24: <Potential Failure 3> | M24: =IF(H24+J24=0," ",H24*J24) | N24: =IF(H24+J24+L24=0,"-",H24*J24*L24) -> - | U24: =IF(R24+S24=0," ",R24*S24) | V24: =IF(R24+S24+T24=0,"-",R24*S24*T24) -> - | AA24: =IF(X24+Y24=0," ",X24*Y24) | AB24: =IF(X24+Y24+Z24=0,"-",X24*Y24*Z24) -> - | AC24: =IF(AB24="-",AD24,IF(AB24>$AE$4,"Very High",IF(AB24>$AE$3,"High",IF(AB24>$AE$2,"Medium",IF(AB24>0,"Low",""))))) -> - | AD24: =IF(N24="-","-",IF(N24>$AE$4,"Very High",IF(N24>$AE$3,"High",IF(N24>$AE$2,"Medium",IF(N24>0,"Low",""))))) -> -
A25: D-10 | C25: <Function 2> | D25: <Potential Failure 1> | M25: =IF(H25+J25=0," ",H25*J25) | N25: =IF(H25+J25+L25=0,"-",H25*J25*L25) -> - | U25: =IF(R25+S25=0," ",R25*S25) | V25: =IF(R25+S25+T25=0,"-",R25*S25*T25) -> - | AA25: =IF(X25+Y25=0," ",X25*Y25) | AB25: =IF(X25+Y25+Z25=0,"-",X25*Y25*Z25) -> - | AC25: =IF(AB25="-",AD25,IF(AB25>$AE$4,"Very High",IF(AB25>$AE$3,"High",IF(AB25>$AE$2,"Medium",IF(AB25>0,"Low",""))))) -> - | AD25: =IF(N25="-","-",IF(N25>$AE$4,"Very High",IF(N25>$AE$3,"High",IF(N25>$AE$2,"Medium",IF(N25>0,"Low",""))))) -> -
A26: D-11 | C26: <Function 3> | D26: <Potential Failure 1> | M26: =IF(H26+J26=0," ",H26*J26) | N26: =IF(H26+J26+L26=0,"-",H26*J26*L26) -> - | U26: =IF(R26+S26=0," ",R26*S26) | V26: =IF(R26+S26+T26=0,"-",R26*S26*T26) -> - | AA26: =IF(X26+Y26=0," ",X26*Y26) | AB26: =IF(X26+Y26+Z26=0,"-",X26*Y26*Z26) -> - | AC26: =IF(AB26="-",AD26,IF(AB26>$AE$4,"Very High",IF(AB26>$AE$3,"High",IF(AB26>$AE$2,"Medium",IF(AB26>0,"Low",""))))) -> - | AD26: =IF(N26="-","-",IF(N26>$AE$4,"Very High",IF(N26>$AE$3,"High",IF(N26>$AE$2,"Medium",IF(N26>0,"Low",""))))) -> -
A27: D-12 | D27: <Potential Failure 2> | M27: =IF(H27+J27=0," ",H27*J27) | N27: =IF(H27+J27+L27=0,"-",H27*J27*L27) -> - | U27: =IF(R27+S27=0," ",R27*S27) | V27: =IF(R27+S27+T27=0,"-",R27*S27*T27) -> - | AA27: =IF(X27+Y27=0," ",X27*Y27) | AB27: =IF(X27+Y27+Z27=0,"-",X27*Y27*Z27) -> - | AC27: =IF(AB27="-",AD27,IF(AB27>$AE$4,"Very High",IF(AB27>$AE$3,"High",IF(AB27>$AE$2,"Medium",IF(AB27>0,"Low",""))))) -> - | AD27: =IF(N27="-","-",IF(N27>$AE$4,"Very High",IF(N27>$AE$3,"High",IF(N27>$AE$2,"Medium",IF(N27>0,"Low",""))))) -> -
A28: D-13 | M28: =IF(H28+J28=0," ",H28*J28) | N28: =IF(H28+J28+L28=0,"-",H28*J28*L28) -> - | U28: =IF(R28+S28=0," ",R28*S28) | V28: =IF(R28+S28+T28=0,"-",R28*S28*T28) -> - | AA28: =IF(X28+Y28=0," ",X28*Y28) | AB28: =IF(X28+Y28+Z28=0,"-",X28*Y28*Z28) -> - | AC28: =IF(AB28="-",AD28,IF(AB28>$AE$4,"Very High",IF(AB28>$AE$3,"High",IF(AB28>$AE$2,"Medium",IF(AB28>0,"Low",""))))) -> - | AD28: =IF(N28="-","-",IF(N28>$AE$4,"Very High",IF(N28>$AE$3,"High",IF(N28>$AE$2,"Medium",IF(N28>0,"Low",""))))) -> -
A29: D-14 | M29: =IF(H29+J29=0," ",H29*J29) | N29: =IF(H29+J29+L29=0,"-",H29*J29*L29) -> - | U29: =IF(R29+S29=0," ",R29*S29) | V29: =IF(R29+S29+T29=0,"-",R29*S29*T29) -> - | AA29: =IF(X29+Y29=0," ",X29*Y29) | AB29: =IF(X29+Y29+Z29=0,"-",X29*Y29*Z29) -> - | AC29: =IF(AB29="-",AD29,IF(AB29>$AE$4,"Very High",IF(AB29>$AE$3,"High",IF(AB29>$AE$2,"Medium",IF(AB29>0,"Low",""))))) -> - | AD29: =IF(N29="-","-",IF(N29>$AE$4,"Very High",IF(N29>$AE$3,"High",IF(N29>$AE$2,"Medium",IF(N29>0,"Low",""))))) -> -
A30: D-15 | M30: =IF(H30+J30=0," ",H30*J30) | N30: =IF(H30+J30+L30=0,"-",H30*J30*L30) -> - | U30: =IF(R30+S30=0," ",R30*S30) | V30: =IF(R30+S30+T30=0,"-",R30*S30*T30) -> - | AA30: =IF(X30+Y30=0," ",X30*Y30) | AB30: =IF(X30+Y30+Z30=0,"-",X30*Y30*Z30) -> - | AC30: =IF(AB30="-",AD30,IF(AB30>$AE$4,"Very High",IF(AB30>$AE$3,"High",IF(AB30>$AE$2,"Medium",IF(AB30>0,"Low",""))))) -> - | AD30: =IF(N30="-","-",IF(N30>$AE$4,"Very High",IF(N30>$AE$3,"High",IF(N30>$AE$2,"Medium",IF(N30>0,"Low",""))))) -> -
A31: D-16 | M31: =IF(H31+J31=0," ",H31*J31) | N31: =IF(H31+J31+L31=0,"-",H31*J31*L31) -> - | U31: =IF(R31+S31=0," ",R31*S31) | V31: =IF(R31+S31+T31=0,"-",R31*S31*T31) -> - | AA31: =IF(X31+Y31=0," ",X31*Y31) | AB31: =IF(X31+Y31+Z31=0,"-",X31*Y31*Z31) -> - | AC31: =IF(AB31="-",AD31,IF(AB31>$AE$4,"Very High",IF(AB31>$AE$3,"High",IF(AB31>$AE$2,"Medium",IF(AB31>0,"Low",""))))) -> - | AD31: =IF(N31="-","-",IF(N31>$AE$4,"Very High",IF(N31>$AE$3,"High",IF(N31>$AE$2,"Medium",IF(N31>0,"Low",""))))) -> -
A32: D-17 | M32: =IF(H32+J32=0," ",H32*J32) | N32: =IF(H32+J32+L32=0,"-",H32*J32*L32) -> - | U32: =IF(R32+S32=0," ",R32*S32) | V32: =IF(R32+S32+T32=0,"-",R32*S32*T32) -> - | AA32: =IF(X32+Y32=0," ",X32*Y32) | AB32: =IF(X32+Y32+Z32=0,"-",X32*Y32*Z32) -> - | AC32: =IF(AB32="-",AD32,IF(AB32>$AE$4,"Very High",IF(AB32>$AE$3,"High",IF(AB32>$AE$2,"Medium",IF(AB32>0,"Low",""))))) -> - | AD32: =IF(N32="-","-",IF(N32>$AE$4,"Very High",IF(N32>$AE$3,"High",IF(N32>$AE$2,"Medium",IF(N32>0,"Low",""))))) -> -
A33: D-18 | M33: =IF(H33+J33=0," ",H33*J33) | N33: =IF(H33+J33+L33=0,"-",H33*J33*L33) -> - | U33: =IF(R33+S33=0," ",R33*S33) | V33: =IF(R33+S33+T33=0,"-",R33*S33*T33) -> - | AA33: =IF(X33+Y33=0," ",X33*Y33) | AB33: =IF(X33+Y33+Z33=0,"-",X33*Y33*Z33) -> - | AC33: =IF(AB33="-",AD33,IF(AB33>$AE$4,"Very High",IF(AB33>$AE$3,"High",IF(AB33>$AE$2,"Medium",IF(AB33>0,"Low",""))))) -> - | AD33: =IF(N33="-","-",IF(N33>$AE$4,"Very High",IF(N33>$AE$3,"High",IF(N33>$AE$2,"Medium",IF(N33>0,"Low",""))))) -> -
A34: D-19 | M34: =IF(H34+J34=0," ",H34*J34) | N34: =IF(H34+J34+L34=0,"-",H34*J34*L34) -> - | U34: =IF(R34+S34=0," ",R34*S34) | V34: =IF(R34+S34+T34=0,"-",R34*S34*T34) -> - | AA34: =IF(X34+Y34=0," ",X34*Y34) | AB34: =IF(X34+Y34+Z34=0,"-",X34*Y34*Z34) -> - | AC34: =IF(AB34="-",AD34,IF(AB34>$AE$4,"Very High",IF(AB34>$AE$3,"High",IF(AB34>$AE$2,"Medium",IF(AB34>0,"Low",""))))) -> - | AD34: =IF(N34="-","-",IF(N34>$AE$4,"Very High",IF(N34>$AE$3,"High",IF(N34>$AE$2,"Medium",IF(N34>0,"Low",""))))) -> -
A35: D-20 | M35: =IF(H35+J35=0," ",H35*J35) | N35: =IF(H35+J35+L35=0,"-",H35*J35*L35) -> - | U35: =IF(R35+S35=0," ",R35*S35) | V35: =IF(R35+S35+T35=0,"-",R35*S35*T35) -> - | AA35: =IF(X35+Y35=0," ",X35*Y35) | AB35: =IF(X35+Y35+Z35=0,"-",X35*Y35*Z35) -> - | AC35: =IF(AB35="-",AD35,IF(AB35>$AE$4,"Very High",IF(AB35>$AE$3,"High",IF(AB35>$AE$2,"Medium",IF(AB35>0,"Low",""))))) -> - | AD35: =IF(N35="-","-",IF(N35>$AE$4,"Very High",IF(N35>$AE$3,"High",IF(N35>$AE$2,"Medium",IF(N35>0,"Low",""))))) -> -
A36: D-21 | M36: =IF(H36+J36=0," ",H36*J36) | N36: =IF(H36+J36+L36=0,"-",H36*J36*L36) -> - | U36: =IF(R36+S36=0," ",R36*S36) | V36: =IF(R36+S36+T36=0,"-",R36*S36*T36) -> - | AA36: =IF(X36+Y36=0," ",X36*Y36) | AB36: =IF(X36+Y36+Z36=0,"-",X36*Y36*Z36) -> - | AC36: =IF(AB36="-",AD36,IF(AB36>$AE$4,"Very High",IF(AB36>$AE$3,"High",IF(AB36>$AE$2,"Medium",IF(AB36>0,"Low",""))))) -> - | AD36: =IF(N36="-","-",IF(N36>$AE$4,"Very High",IF(N36>$AE$3,"High",IF(N36>$AE$2,"Medium",IF(N36>0,"Low",""))))) -> -
A37: D-22 | M37: =IF(H37+J37=0," ",H37*J37) | N37: =IF(H37+J37+L37=0,"-",H37*J37*L37) -> - | U37: =IF(R37+S37=0," ",R37*S37) | V37: =IF(R37+S37+T37=0,"-",R37*S37*T37) -> - | AA37: =IF(X37+Y37=0," ",X37*Y37) | AB37: =IF(X37+Y37+Z37=0,"-",X37*Y37*Z37) -> - | AC37: =IF(AB37="-",AD37,IF(AB37>$AE$4,"Very High",IF(AB37>$AE$3,"High",IF(AB37>$AE$2,"Medium",IF(AB37>0,"Low",""))))) -> - | AD37: =IF(N37="-","-",IF(N37>$AE$4,"Very High",IF(N37>$AE$3,"High",IF(N37>$AE$2,"Medium",IF(N37>0,"Low",""))))) -> -
A38: D-23 | M38: =IF(H38+J38=0," ",H38*J38) | N38: =IF(H38+J38+L38=0,"-",H38*J38*L38) -> - | U38: =IF(R38+S38=0," ",R38*S38) | V38: =IF(R38+S38+T38=0,"-",R38*S38*T38) -> - | AA38: =IF(X38+Y38=0," ",X38*Y38) | AB38: =IF(X38+Y38+Z38=0,"-",X38*Y38*Z38) -> - | AC38: =IF(AB38="-",AD38,IF(AB38>$AE$4,"Very High",IF(AB38>$AE$3,"High",IF(AB38>$AE$2,"Medium",IF(AB38>0,"Low",""))))) -> - | AD38: =IF(N38="-","-",IF(N38>$AE$4,"Very High",IF(N38>$AE$3,"High",IF(N38>$AE$2,"Medium",IF(N38>0,"Low",""))))) -> -
A39: D-24 | M39: =IF(H39+J39=0," ",H39*J39) | N39: =IF(H39+J39+L39=0,"-",H39*J39*L39) -> - | U39: =IF(R39+S39=0," ",R39*S39) | V39: =IF(R39+S39+T39=0,"-",R39*S39*T39) -> - | AA39: =IF(X39+Y39=0," ",X39*Y39) | AB39: =IF(X39+Y39+Z39=0,"-",X39*Y39*Z39) -> - | AC39: =IF(AB39="-",AD39,IF(AB39>$AE$4,"Very High",IF(AB39>$AE$3,"High",IF(AB39>$AE$2,"Medium",IF(AB39>0,"Low",""))))) -> - | AD39: =IF(N39="-","-",IF(N39>$AE$4,"Very High",IF(N39>$AE$3,"High",IF(N39>$AE$2,"Medium",IF(N39>0,"Low",""))))) -> -
... A42: D-27 | M42: =IF(H42+J42=0," ",H42*J42) | N42: =IF(H42+J42+L42=0,"-",H42*J42*L42) -> - | U42: =IF(R42+S42=0," ",R42*S42) | V42: =IF(R42+S42+T42=0,"-",R42*S42*T42) -> - | AA42: =IF(X42+Y42=0," ",X42*Y42) | AB42: =IF(X42+Y42+Z42=0,"-",X42*Y42*Z42) -> - | AC42: =IF(AB42="-",AD42,IF(AB42>$AE$4,"Very High",IF(AB42>$AE$3,"High",IF(AB42>$AE$2,"Medium",IF(AB42>0,"Low",""))))) -> - | AD42: =IF(N42="-","-",IF(N42>$AE$4,"Very High",IF(N42>$AE$3,"High",IF(N42>$AE$2,"Medium",IF(N42>0,"Low",""))))) -> -

Sheet Produit rapport
E2: Produit Risk Follow-up.
B3: =TODAY() -> 46071 | E3: Date | F3: Example KOM
B4: =COUNTIF(Produit!AC16:AC42,"VERY HIGH") -> 0 | D4: RPN | E4: Very High | F4: 0
B5: =COUNTIF(Produit!AC16:AC42,"HIGH") -> 0 | E5: High | F5: 1
B6: =COUNTIF(Produit!AC16:AC42,"MEDIUM") -> 0 | E6: Medium | F6: 1
B7: =COUNTIF(Produit!AC16:AC42,"LOW") -> 4 | E7: Low | F7: 2
